Workbook
Name Agrupación: [1]Parámetros!$C$5:$C$6

Sheet BDD
B2: Fecha | C2: Intervalo | D2: Cola | E2: Tipo de medios | F2: Ofrecidas | G2: Contestadas | H2: Abandonadas | I2: % de nivel de servicio | J2: AHT | K2: Fecha2 | L2: NDA INT | M2: Aten < 20 seg | N2: cosas | O2: NDS Int | P2: TMO | Q2: Skill | R2: Skill2 | T2: Cola | U2: Agrupación
B3: 46204 | C3: 0.375 | D3: BUPA_Seguros_Empresas_Otras_Consultas | E3: voz | F3: 1 | G3: 1 | H3: 0 | I3: 0 | J3: None | K3: =INT(Regiones[[#This Row],[Fecha]]) -> 46204 | L3: =IFERROR(Regiones[[#This Row],[Contestadas]]/Regiones[[#This Row],[Ofrecidas]],"") -> 1 | M3: =IFERROR(Regiones[[#This Row],[Ofrecidas]]*Regiones[[#This Row],[% de nivel de servicio]],"") -> 0 | O3: =IFERROR(Regiones[[#This Row],[Aten < 20 seg]]/Regiones[[#This Row],[Contestadas]],"") -> 0 | P3: =IFERROR(Regiones[[#This Row],[AHT]]*86400,"error") -> error | Q3: =+VLOOKUP(Regiones[[#This Row],[Cola]],Tabla6[#Data],2,0) -> BUPA | R3: =+VLOOKUP(Regiones[[#This Row],[Cola]],Tabla68[],2,0) -> #N/A | T3: BUPA_Cambio_medio_de_pago | U3: BUPA
B4: 46204 | C4: 0.375 | D4: BUPA_Servicio_al_Cliente_Nacional | E4: voz | F4: 2 | G4: 2 | H4: 0 | I4: 0.5 | J4: 0.0057986111 | K4: =INT(Regiones[[#This Row],[Fecha]]) -> 46204 | L4: =IFERROR(Regiones[[#This Row],[Contestadas]]/Regiones[[#This Row],[Ofrecidas]],"") -> 1 | M4: =IFERROR(Regiones[[#This Row],[Ofrecidas]]*Regiones[[#This Row],[% de nivel de servicio]],"") -> 1 | O4: =IFERROR(Regiones[[#This Row],[Aten < 20 seg]]/Regiones[[#This Row],[Contestadas]],"") -> 0.5 | P4: =IFERROR(Regiones[[#This Row],[AHT]]*86400,"error") -> 501 | Q4: =+VLOOKUP(Regiones[[#This Row],[Cola]],Tabla6[#Data],2,0) -> BUPA | R4: =+VLOOKUP(Regiones[[#This Row],[Cola]],Tabla68[],2,0) -> #N/A | T4: BUPA_Cobros | U4: BUPA
B5: 46204 | C5: 0.375 | D5: BUPA_Otras_Consultas | E5: voz | F5: 15 | G5: 14 | H5: 1 | I5: 0.47 | J5: 0.0046064815 | K5: =INT(Regiones[[#This Row],[Fecha]]) -> 46204 | L5: =IFERROR(Regiones[[#This Row],[Contestadas]]/Regiones[[#This Row],[Ofrecidas]],"") -> 0.93333333 | M5: =IFERROR(Regiones[[#This Row],[Ofrecidas]]*Regiones[[#This Row],[% de nivel de servicio]],"") -> 7.05 | O5: =IFERROR(Regiones[[#This Row],[Aten < 20 seg]]/Regiones[[#This Row],[Contestadas]],"") -> 0.50357143 | P5: =IFERROR(Regiones[[#This Row],[AHT]]*86400,"error") -> 398 | Q5: =+VLOOKUP(Regiones[[#This Row],[Cola]],Tabla6[#Data],2,0) -> BUPA | R5: =+VLOOKUP(Regiones[[#This Row],[Cola]],Tabla68[],2,0) -> #N/A | T5: BUPA_Otras_Consultas | U5: BUPA
B6: 46204 | C6: 0.375 | D6: BUPA_Reembolsos | E6: voz | F6: 3 | G6: 3 | H6: 0 | I6: 0.33 | J6: 0.0044560185 | K6: =INT(Regiones[[#This Row],[Fecha]]) -> 46204 | L6: =IFERROR(Regiones[[#This Row],[Contestadas]]/Regiones[[#This Row],[Ofrecidas]],"") -> 1 | M6: =IFERROR(Regiones[[#This Row],[Ofrecidas]]*Regiones[[#This Row],[% de nivel de servicio]],"") -> 0.99 | O6: =IFERROR(Regiones[[#This Row],[Aten < 20 seg]]/Regiones[[#This Row],[Contestadas]],"") -> 0.33 | P6: =IFERROR(Regiones[[#This Row],[AHT]]*86400,"error") -> 385 | Q6: =+VLOOKUP(Regiones[[#This Row],[Cola]],Tabla6[#Data],2,0) -> BUPA | R6: =+VLOOKUP(Regiones[[#This Row],[Cola]],Tabla68[],2,0) -> #N/A | T6: BUPA_Reembolsos | U6: BUPA
B7: 46204 | C7: 0.375 | D7: BUPA_Consulta_Liquidacion_Reembolso | E7: voz | F7: 1 | G7: 1 | H7: 0 | I7: 0 | J7: 0.0047222222 | K7: =INT(Regiones[[#This Row],[Fecha]]) -> 46204 | L7: =IFERROR(Regiones[[#This Row],[Contestadas]]/Regiones[[#This Row],[Ofrecidas]],"") -> 1 | M7: =IFERROR(Regiones[[#This Row],[Ofrecidas]]*Regiones[[#This Row],[% de nivel de servicio]],"") -> 0 | O7: =IFERROR(Regiones[[#This Row],[Aten < 20 seg]]/Regiones[[#This Row],[Contestadas]],"") -> 0 | P7: =IFERROR(Regiones[[#This Row],[AHT]]*86400,"error") -> 408 | Q7: =+VLOOKUP(Regiones[[#This Row],[Cola]],Tabla6[#Data],2,0) -> BUPA | R7: =+VLOOKUP(Regiones[[#This Row],[Cola]],Tabla68[],2,0) -> #N/A | T7: BUPA_Servicio_al_Cliente_Nacional | U7: BUPA
B8: 46204 | C8: 0.375 | D8: BUPA_Cobros | E8: voz | F8: 13 | G8: 13 | H8: 0 | I8: 0.46 | J8: 0.0051157407 | K8: =INT(Regiones[[#This Row],[Fecha]]) -> 46204 | L8: =IFERROR(Regiones[[#This Row],[Contestadas]]/Regiones[[#This Row],[Ofrecidas]],"") -> 1 | M8: =IFERROR(Regiones[[#This Row],[Ofrecidas]]*Regiones[[#This Row],[% de nivel de servicio]],"") -> 5.98 | O8: =IFERROR(Regiones[[#This Row],[Aten < 20 seg]]/Regiones[[#This Row],[Contestadas]],"") -> 0.46 | P8: =IFERROR(Regiones[[#This Row],[AHT]]*86400,"error") -> 442 | Q8: =+VLOOKUP(Regiones[[#This Row],[Cola]],Tabla6[#Data],2,0) -> BUPA | R8: =+VLOOKUP(Regiones[[#This Row],[Cola]],Tabla68[],2,0) -> #N/A | T8: BUPA_Seguro_Colectivo_Representante | U8: BUPA
B9: 46204 | C9: 0.375 | D9: BUPA_Cambio_medio_de_pago | E9: voz | F9: 2 | G9: 2 | H9: 0 | I9: 0 | J9: 0.0031018519 | K9: =INT(Regiones[[#This Row],[Fecha]]) -> 46204 | L9: =IFERROR(Regiones[[#This Row],[Contestadas]]/Regiones[[#This Row],[Ofrecidas]],"") -> 1 | M9: =IFERROR(Regiones[[#This Row],[Ofrecidas]]*Regiones[[#This Row],[% de nivel de servicio]],"") -> 0 | O9: =IFERROR(Regiones[[#This Row],[Aten < 20 seg]]/Regiones[[#This Row],[Contestadas]],"") -> 0 | P9: =IFERROR(Regiones[[#This Row],[AHT]]*86400,"error") -> 268 | Q9: =+VLOOKUP(Regiones[[#This Row],[Cola]],Tabla6[#Data],2,0) -> BUPA | R9: =+VLOOKUP(Regiones[[#This Row],[Cola]],Tabla68[],2,0) -> #N/A | T9: BUPA_Acceso_Web | U9: BUPA
B10: 46204 | C10: 0.39583333 | D10: BUPA_Acceso_Web | E10: voz | F10: 1 | G10: 1 | H10: 0 | I10: 1 | J10: 0.001412037 | K10: =INT(Regiones[[#This Row],[Fecha]]) -> 46204 | L10: =IFERROR(Regiones[[#This Row],[Contestadas]]/Regiones[[#This Row],[Ofrecidas]],"") -> 1 | M10: =IFERROR(Regiones[[#This Row],[Ofrecidas]]*Regiones[[#This Row],[% de nivel de servicio]],"") -> 1 | O10: =IFERROR(Regiones[[#This Row],[Aten < 20 seg]]/Regiones[[#This Row],[Contestadas]],"") -> 1 | P10: =IFERROR(Regiones[[#This Row],[AHT]]*86400,"error") -> 122 | Q10: =+VLOOKUP(Regiones[[#This Row],[Cola]],Tabla6[#Data],2,0) -> BUPA | R10: =+VLOOKUP(Regiones[[#This Row],[Cola]],Tabla68[],2,0) -> #N/A | T10: BUPA_Consulta_Liquidacion_Reembolso | U10: BUPA
B11: 46204 | C11: 0.39583333 | D11: BUPA_Reembolsos | E11: voz | F11: 8 | G11: 8 | H11: 0 | I11: 1 | J11: 0.002974537 | K11: =INT(Regiones[[#This Row],[Fecha]]) -> 46204 | L11: =IFERROR(Regiones[[#This Row],[Contestadas]]/Regiones[[#This Row],[Ofrecidas]],"") -> 1 | M11: =IFERROR(Regiones[[#This Row],[Ofrecidas]]*Regiones[[#This Row],[% de nivel de servicio]],"") -> 8 | O11: =IFERROR(Regiones[[#This Row],[Aten < 20 seg]]/Regiones[[#This Row],[Contestadas]],"") -> 1 | P11: =IFERROR(Regiones[[#This Row],[AHT]]*86400,"error") -> 257 | Q11: =+VLOOKUP(Regiones[[#This Row],[Cola]],Tabla6[#Data],2,0) -> BUPA | R11: =+VLOOKUP(Regiones[[#This Row],[Cola]],Tabla68[],2,0) -> #N/A | T11: BUPA_Consultas_Cobertura | U11: BUPA
B12: 46204 | C12: 0.39583333 | D12: BUPA_Cambio_medio_de_pago | E12: voz | F12: 1 | G12: 1 | H12: 0 | I12: 0 | J12: 0.0048726852 | K12: =INT(Regiones[[#This Row],[Fecha]]) -> 46204 | L12: =IFERROR(Regiones[[#This Row],[Contestadas]]/Regiones[[#This Row],[Ofrecidas]],"") -> 1 | M12: =IFERROR(Regiones[[#This Row],[Ofrecidas]]*Regiones[[#This Row],[% de nivel de servicio]],"") -> 0 | O12: =IFERROR(Regiones[[#This Row],[Aten < 20 seg]]/Regiones[[#This Row],[Contestadas]],"") -> 0 | P12: =IFERROR(Regiones[[#This Row],[AHT]]*86400,"error") -> 421 | Q12: =+VLOOKUP(Regiones[[#This Row],[Cola]],Tabla6[#Data],2,0) -> BUPA | R12: =+VLOOKUP(Regiones[[#This Row],[Cola]],Tabla68[],2,0) -> #N/A | T12: BUPA_Modificacion_Datos_Personales | U12: BUPA
B13: 46204 | C13: 0.39583333 | D13: BUPA_Otras_Consultas | E13: voz | F13: 21 | G13: 18 | H13: 0 | I13: 0.78 | J13: 0.0038078704 | K13: =INT(Regiones[[#This Row],[Fecha]]) -> 46204 | L13: =IFERROR(Regiones[[#This Row],[Contestadas]]/Regiones[[#This Row],[Ofrecidas]],"") -> 0.85714286 | M13: =IFERROR(Regiones[[#This Row],[Ofrecidas]]*Regiones[[#This Row],[% de nivel de servicio]],"") -> 16.38 | O13: =IFERROR(Regiones[[#This Row],[Aten < 20 seg]]/Regiones[[#This Row],[Contestadas]],"") -> 0.91 | P13: =IFERROR(Regiones[[#This Row],[AHT]]*86400,"error") -> 329 | Q13: =+VLOOKUP(Regiones[[#This Row],[Cola]],Tabla6[#Data],2,0) -> BUPA | R13: =+VLOOKUP(Regiones[[#This Row],[Cola]],Tabla68[],2,0) -> #N/A | T13: BUPA_Seguros_Empresas_Otras_Consultas | U13: BUPA
B14: 46204 | C14: 0.39583333 | D14: BUPA_Cobros | E14: voz | F14: 11 | G14: 10 | H14: 0 | I14: 0.9 | J14: 0.0042708333 | K14: =INT(Regiones[[#This Row],[Fecha]]) -> 46204 | L14: =IFERROR(Regiones[[#This Row],[Contestadas]]/Regiones[[#This Row],[Ofrecidas]],"") -> 0.90909091 | M14: =IFERROR(Regiones[[#This Row],[Ofrecidas]]*Regiones[[#This Row],[% de nivel de servicio]],"") -> 9.9 | O14: =IFERROR(Regiones[[#This Row],[Aten < 20 seg]]/Regiones[[#This Row],[Contestadas]],"") -> 0.99 | P14: =IFERROR(Regiones[[#This Row],[AHT]]*86400,"error") -> 369 | Q14: =+VLOOKUP(Regiones[[#This Row],[Cola]],Tabla6[#Data],2,0) -> BUPA | R14: =+VLOOKUP(Regiones[[#This Row],[Cola]],Tabla68[],2,0) -> #N/A | T14: Cola | U14: Agrupación
B15: 46204 | C15: 0.39583333 | D15: BUPA_Modificacion_Datos_Personales | E15: voz | F15: 1 | G15: 1 | H15: 0 | I15: 1 | J15: 0.0067939815 | K15: =INT(Regiones[[#This Row],[Fecha]]) -> 46204 | L15: =IFERROR(Regiones[[#This Row],[Contestadas]]/Regiones[[#This Row],[Ofrecidas]],"") -> 1 | M15: =IFERROR(Regiones[[#This Row],[Ofrecidas]]*Regiones[[#This Row],[% de nivel de servicio]],"") -> 1 | O15: =IFERROR(Regiones[[#This Row],[Aten < 20 seg]]/Regiones[[#This Row],[Contestadas]],"") -> 1 | P15: =IFERROR(Regiones[[#This Row],[AHT]]*86400,"error") -> 587 | Q15: =+VLOOKUP(Regiones[[#This Row],[Cola]],Tabla6[#Data],2,0) -> BUPA | R15: =+VLOOKUP(Regiones[[#This Row],[Cola]],Tabla68[],2,0) -> #N/A
B16: 46204 | C16: 0.39583333 | D16: BUPA_Seguros_Empresas_Otras_Consultas | E16: voz | F16: 3 | G16: 2 | H16: 1 | I16: 0.67 | J16: 0.0084953704 | K16: =INT(Regiones[[#This Row],[Fecha]]) -> 46204 | L16: =IFERROR(Regiones[[#This Row],[Contestadas]]/Regiones[[#This Row],[Ofrecidas]],"") -> 0.66666667 | M16: =IFERROR(Regiones[[#This Row],[Ofrecidas]]*Regiones[[#This Row],[% de nivel de servicio]],"") -> 2.01 | O16: =IFERROR(Regiones[[#This Row],[Aten < 20 seg]]/Regiones[[#This Row],[Contestadas]],"") -> 1.005 | P16: =IFERROR(Regiones[[#This Row],[AHT]]*86400,"error") -> 734 | Q16: =+VLOOKUP(Regiones[[#This Row],[Cola]],Tabla6[#Data],2,0) -> BUPA | R16: =+VLOOKUP(Regiones[[#This Row],[Cola]],Tabla68[],2,0) -> #N/A
B17: 46204 | C17: 0.41666667 | D17: BUPA_Seguros_Empresas_Otras_Consultas | E17: voz | F17: 2 | G17: 0 | H17: 2 | I17: 0 | J17: None | K17: =INT(Regiones[[#This Row],[Fecha]]) -> 46204 | L17: =IFERROR(Regiones[[#This Row],[Contestadas]]/Regiones[[#This Row],[Ofrecidas]],"") -> 0 | M17: =IFERROR(Regiones[[#This Row],[Ofrecidas]]*Regiones[[#This Row],[% de nivel de servicio]],"") -> 0 | O17: =IFERROR(Regiones[[#This Row],[Aten < 20 seg]]/Regiones[[#This Row],[Contestadas]],"") | P17: =IFERROR(Regiones[[#This Row],[AHT]]*86400,"error") -> error | Q17: =+VLOOKUP(Regiones[[#This Row],[Cola]],Tabla6[#Data],2,0) -> BUPA | R17: =+VLOOKUP(Regiones[[#This Row],[Cola]],Tabla68[],2,0) -> #N/A
B18: 46204 | C18: 0.41666667 | D18: BUPA_Servicio_al_Cliente_Nacional | E18: voz | F18: 1 | G18: 1 | H18: 0 | I18: 0 | J18: None | K18: =INT(Regiones[[#This Row],[Fecha]]) -> 46204 | L18: =IFERROR(Regiones[[#This Row],[Contestadas]]/Regiones[[#This Row],[Ofrecidas]],"") -> 1 | M18: =IFERROR(Regiones[[#This Row],[Ofrecidas]]*Regiones[[#This Row],[% de nivel de servicio]],"") -> 0 | O18: =IFERROR(Regiones[[#This Row],[Aten < 20 seg]]/Regiones[[#This Row],[Contestadas]],"") -> 0 | P18: =IFERROR(Regiones[[#This Row],[AHT]]*86400,"error") -> error | Q18: =+VLOOKUP(Regiones[[#This Row],[Cola]],Tabla6[#Data],2,0) -> BUPA | R18: =+VLOOKUP(Regiones[[#This Row],[Cola]],Tabla68[],2,0) -> #N/A
B19: 46204 | C19: 0.41666667 | D19: BUPA_Consulta_Liquidacion_Reembolso | E19: voz | F19: 3 | G19: 3 | H19: 0 | I19: 0 | J19: 0.0032986111 | K19: =INT(Regiones[[#This Row],[Fecha]]) -> 46204 | L19: =IFERROR(Regiones[[#This Row],[Contestadas]]/Regiones[[#This Row],[Ofrecidas]],"") -> 1 | M19: =IFERROR(Regiones[[#This Row],[Ofrecidas]]*Regiones[[#This Row],[% de nivel de servicio]],"") -> 0 | O19: =IFERROR(Regiones[[#This Row],[Aten < 20 seg]]/Regiones[[#This Row],[Contestadas]],"") -> 0 | P19: =IFERROR(Regiones[[#This Row],[AHT]]*86400,"error") -> 285 | Q19: =+VLOOKUP(Regiones[[#This Row],[Cola]],Tabla6[#Data],2,0) -> BUPA | R19: =+VLOOKUP(Regiones[[#This Row],[Cola]],Tabla68[],2,0) -> #N/A
B20: 46204 | C20: 0.41666667 | D20: BUPA_Reembolsos | E20: voz | F20: 13 | G20: 6 | H20: 4 | I20: 0 | J20: 0.0056018519 | K20: =INT(Regiones[[#This Row],[Fecha]]) -> 46204 | L20: =IFERROR(Regiones[[#This Row],[Contestadas]]/Regiones[[#This Row],[Ofrecidas]],"") -> 0.46153846 | M20: =IFERROR(Regiones[[#This Row],[Ofrecidas]]*Regiones[[#This Row],[% de nivel de servicio]],"") -> 0 | O20: =IFERROR(Regiones[[#This Row],[Aten < 20 seg]]/Regiones[[#This Row],[Contestadas]],"") -> 0 | P20: =IFERROR(Regiones[[#This Row],[AHT]]*86400,"error") -> 484 | Q20: =+VLOOKUP(Regiones[[#This Row],[Cola]],Tabla6[#Data],2,0) -> BUPA | R20: =+VLOOKUP(Regiones[[#This Row],[Cola]],Tabla68[],2,0) -> #N/A
B21: 46204 | C21: 0.41666667 | D21: BUPA_Cambio_medio_de_pago | E21: voz | F21: 4 | G21: 4 | H21: 0 | I21: 0 | J21: 0.0060300926 | K21: =INT(Regiones[[#This Row],[Fecha]]) -> 46204 | L21: =IFERROR(Regiones[[#This Row],[Contestadas]]/Regiones[[#This Row],[Ofrecidas]],"") -> 1 | M21: =IFERROR(Regiones[[#This Row],[Ofrecidas]]*Regiones[[#This Row],[% de nivel de servicio]],"") -> 0 | O21: =IFERROR(Regiones[[#This Row],[Aten < 20 seg]]/Regiones[[#This Row],[Contestadas]],"") -> 0 | P21: =IFERROR(Regiones[[#This Row],[AHT]]*86400,"error") -> 521 | Q21: =+VLOOKUP(Regiones[[#This Row],[Cola]],Tabla6[#Data],2,0) -> BUPA | R21: =+VLOOKUP(Regiones[[#This Row],[Cola]],Tabla68[],2,0) -> #N/A
B22: 46204 | C22: 0.41666667 | D22: BUPA_Otras_Consultas | E22: voz | F22: 13 | G22: 11 | H22: 4 | I22: 0 | J22: 0.008275463 | K22: =INT(Regiones[[#This Row],[Fecha]]) -> 46204 | L22: =IFERROR(Regiones[[#This Row],[Contestadas]]/Regiones[[#This Row],[Ofrecidas]],"") -> 0.84615385 | M22: =IFERROR(Regiones[[#This Row],[Ofrecidas]]*Regiones[[#This Row],[% de nivel de servicio]],"") -> 0 | O22: =IFERROR(Regiones[[#This Row],[Aten < 20 seg]]/Regiones[[#This Row],[Contestadas]],"") -> 0 | P22: =IFERROR(Regiones[[#This Row],[AHT]]*86400,"error") -> 715 | Q22: =+VLOOKUP(Regiones[[#This Row],[Cola]],Tabla6[#Data],2,0) -> BUPA | R22: =+VLOOKUP(Regiones[[#This Row],[Cola]],Tabla68[],2,0) -> #N/A
B23: 46204 | C23: 0.41666667 | D23: BUPA_Cobros | E23: voz | F23: 14 | G23: 12 | H23: 3 | I23: 0.2 | J23: 0.0043634259 | K23: =INT(Regiones[[#This Row],[Fecha]]) -> 46204 | L23: =IFERROR(Regiones[[#This Row],[Contestadas]]/Regiones[[#This Row],[Ofrecidas]],"") -> 0.85714286 | M23: =IFERROR(Regiones[[#This Row],[Ofrecidas]]*Regiones[[#This Row],[% de nivel de servicio]],"") -> 2.8 | O23: =IFERROR(Regiones[[#This Row],[Aten < 20 seg]]/Regiones[[#This Row],[Contestadas]],"") -> 0.23333333 | P23: =IFERROR(Regiones[[#This Row],[AHT]]*86400,"error") -> 377 | Q23: =+VLOOKUP(Regiones[[#This Row],[Cola]],Tabla6[#Data],2,0) -> BUPA | R23: =+VLOOKUP(Regiones[[#This Row],[Cola]],Tabla68[],2,0) -> #N/A
B24: 46204 | C24: 0.4375 | D24: BUPA_Consulta_Liquidacion_Reembolso | E24: voz | F24: 6 | G24: 3 | H24: 2 | I24: 0 | J24: 0.0024189815 | K24: =INT(Regiones[[#This Row],[Fecha]]) -> 46204 | L24: =IFERROR(Regiones[[#This Row],[Contestadas]]/Regiones[[#This Row],[Ofrecidas]],"") -> 0.5 | M24: =IFERROR(Regiones[[#This Row],[Ofrecidas]]*Regiones[[#This Row],[% de nivel de servicio]],"") -> 0 | O24: =IFERROR(Regiones[[#This Row],[Aten < 20 seg]]/Regiones[[#This Row],[Contestadas]],"") -> 0 | P24: =IFERROR(Regiones[[#This Row],[AHT]]*86400,"error") -> 209 | Q24: =+VLOOKUP(Regiones[[#This Row],[Cola]],Tabla6[#Data],2,0) -> BUPA | R24: =+VLOOKUP(Regiones[[#This Row],[Cola]],Tabla68[],2,0) -> #N/A
B25: 46204 | C25: 0.4375 | D25: BUPA_Cobros | E25: voz | F25: 7 | G25: 7 | H25: 0 | I25: 0.57 | J25: 0.0066550926 | K25: =INT(Regiones[[#This Row],[Fecha]]) -> 46204 | L25: =IFERROR(Regiones[[#This Row],[Contestadas]]/Regiones[[#This Row],[Ofrecidas]],"") -> 1 | M25: =IFERROR(Regiones[[#This Row],[Ofrecidas]]*Regiones[[#This Row],[% de nivel de servicio]],"") -> 3.99 | O25: =IFERROR(Regiones[[#This Row],[Aten < 20 seg]]/Regiones[[#This Row],[Contestadas]],"") -> 0.57 | P25: =IFERROR(Regiones[[#This Row],[AHT]]*86400,"error") -> 575 | Q25: =+VLOOKUP(Regiones[[#This Row],[Cola]],Tabla6[#Data],2,0) -> BUPA | R25: =+VLOOKUP(Regiones[[#This Row],[Cola]],Tabla68[],2,0) -> #N/A
B26: 46204 | C26: 0.4375 | D26: BUPA_Consultas_Cobertura | E26: voz | F26: 1 | G26: 1 | H26: 0 | I26: 0 | J26: 0.0014930556 | K26: =INT(Regiones[[#This Row],[Fecha]]) -> 46204 | L26: =IFERROR(Regiones[[#This Row],[Contestadas]]/Regiones[[#This Row],[Ofrecidas]],"") -> 1 | M26: =IFERROR(Regiones[[#This Row],[Ofrecidas]]*Regiones[[#This Row],[% de nivel de servicio]],"") -> 0 | O26: =IFERROR(Regiones[[#This Row],[Aten < 20 seg]]/Regiones[[#This Row],[Contestadas]],"") -> 0 | P26: =IFERROR(Regiones[[#This Row],[AHT]]*86400,"error") -> 129 | Q26: =+VLOOKUP(Regiones[[#This Row],[Cola]],Tabla6[#Data],2,0) -> BUPA | R26: =+VLOOKUP(Regiones[[#This Row],[Cola]],Tabla68[],2,0) -> #N/A
B27: 46204 | C27: 0.4375 | D27: BUPA_Reembolsos | E27: voz | F27: 11 | G27: 11 | H27: 3 | I27: 0 | J27: 0.0052662037 | K27: =INT(Regiones[[#This Row],[Fecha]]) -> 46204 | L27: =IFERROR(Regiones[[#This Row],[Contestadas]]/Regiones[[#This Row],[Ofrecidas]],"") -> 1 | M27: =IFERROR(Regiones[[#This Row],[Ofrecidas]]*Regiones[[#This Row],[% de nivel de servicio]],"") -> 0 | O27: =IFERROR(Regiones[[#This Row],[Aten < 20 seg]]/Regiones[[#This Row],[Contestadas]],"") -> 0 | P27: =IFERROR(Regiones[[#This Row],[AHT]]*86400,"error") -> 455 | Q27: =+VLOOKUP(Regiones[[#This Row],[Cola]],Tabla6[#Data],2,0) -> BUPA | R27: =+VLOOKUP(Regiones[[#This Row],[Cola]],Tabla68[],2,0) -> #N/A
B28: 46204 | C28: 0.4375 | D28: BUPA_Otras_Consultas | E28: voz | F28: 20 | G28: 11 | H28: 6 | I28: 0 | J28: 0.0044560185 | K28: =INT(Regiones[[#This Row],[Fecha]]) -> 46204 | L28: =IFERROR(Regiones[[#This Row],[Contestadas]]/Regiones[[#This Row],[Ofrecidas]],"") -> 0.55 | M28: =IFERROR(Regiones[[#This Row],[Ofrecidas]]*Regiones[[#This Row],[% de nivel de servicio]],"") -> 0 | O28: =IFERROR(Regiones[[#This Row],[Aten < 20 seg]]/Regiones[[#This Row],[Contestadas]],"") -> 0 | P28: =IFERROR(Regiones[[#This Row],[AHT]]*86400,"error") -> 385 | Q28: =+VLOOKUP(Regiones[[#This Row],[Cola]],Tabla6[#Data],2,0) -> BUPA | R28: =+VLOOKUP(Regiones[[#This Row],[Cola]],Tabla68[],2,0) -> #N/A
B29: 46204 | C29: 0.4375 | D29: BUPA_Cambio_medio_de_pago | E29: voz | F29: 1 | G29: 1 | H29: 0 | I29: 0 | J29: 0.00082175926 | K29: =INT(Regiones[[#This Row],[Fecha]]) -> 46204 | L29: =IFERROR(Regiones[[#This Row],[Contestadas]]/Regiones[[#This Row],[Ofrecidas]],"") -> 1 | M29: =IFERROR(Regiones[[#This Row],[Ofrecidas]]*Regiones[[#This Row],[% de nivel de servicio]],"") -> 0 | O29: =IFERROR(Regiones[[#This Row],[Aten < 20 seg]]/Regiones[[#This Row],[Contestadas]],"") -> 0 | P29: =IFERROR(Regiones[[#This Row],[AHT]]*86400,"error") -> 71 | Q29: =+VLOOKUP(Regiones[[#This Row],[Cola]],Tabla6[#Data],2,0) -> BUPA | R29: =+VLOOKUP(Regiones[[#This Row],[Cola]],Tabla68[],2,0) -> #N/A
B30: 46204 | C30: 0.4375 | D30: BUPA_Servicio_al_Cliente_Nacional | E30: voz | F30: 3 | G30: 1 | H30: 1 | I30: 0 | J30: 0.0087847222 | K30: =INT(Regiones[[#This Row],[Fecha]]) -> 46204 | L30: =IFERROR(Regiones[[#This Row],[Contestadas]]/Regiones[[#This Row],[Ofrecidas]],"") -> 0.33333333 | M30: =IFERROR(Regiones[[#This Row],[Ofrecidas]]*Regiones[[#This Row],[% de nivel de servicio]],"") -> 0 | O30: =IFERROR(Regiones[[#This Row],[Aten < 20 seg]]/Regiones[[#This Row],[Contestadas]],"") -> 0 | P30: =IFERROR(Regiones[[#This Row],[AHT]]*86400,"error") -> 759 | Q30: =+VLOOKUP(Regiones[[#This Row],[Cola]],Tabla6[#Data],2,0) -> BUPA | R30: =+VLOOKUP(Regiones[[#This Row],[Cola]],Tabla68[],2,0) -> #N/A
B31: 46204 | C31: 0.4375 | D31: BUPA_Seguro_Colectivo_Representante | E31: voz | F31: 1 | G31: 0 | H31: 0 | I31: nan | J31: None | K31: =INT(Regiones[[#This Row],[Fecha]]) -> 46204 | L31: =IFERROR(Regiones[[#This Row],[Contestadas]]/Regiones[[#This Row],[Ofrecidas]],"") -> 0 | M31: =IFERROR(Regiones[[#This Row],[Ofrecidas]]*Regiones[[#This Row],[% de nivel de servicio]],"") | O31: =IFERROR(Regiones[[#This Row],[Aten < 20 seg]]/Regiones[[#This Row],[Contestadas]],"") | P31: =IFERROR(Regiones[[#This Row],[AHT]]*86400,"error") -> error | Q31: =+VLOOKUP(Regiones[[#This Row],[Cola]],Tabla6[#Data],2,0) -> BUPA | R31: =+VLOOKUP(Regiones[[#This Row],[Cola]],Tabla68[],2,0) -> #N/A
B32: 46204 | C32: 0.4375 | D32: BUPA_Seguros_Empresas_Otras_Consultas | E32: voz | F32: 2 | G32: 2 | H32: 0 | I32: 0 | J32: 0.0039351852 | K32: =INT(Regiones[[#This Row],[Fecha]]) -> 46204 | L32: =IFERROR(Regiones[[#This Row],[Contestadas]]/Regiones[[#This Row],[Ofrecidas]],"") -> 1 | M32: =IFERROR(Regiones[[#This Row],[Ofrecidas]]*Regiones[[#This Row],[% de nivel de servicio]],"") -> 0 | O32: =IFERROR(Regiones[[#This Row],[Aten < 20 seg]]/Regiones[[#This Row],[Contestadas]],"") -> 0 | P32: =IFERROR(Regiones[[#This Row],[AHT]]*86400,"error") -> 340 | Q32: =+VLOOKUP(Regiones[[#This Row],[Cola]],Tabla6[#Data],2,0) -> BUPA | R32: =+VLOOKUP(Regiones[[#This Row],[Cola]],Tabla68[],2,0) -> #N/A
B33: 46204 | C33: 0.45833333 | D33: BUPA_Seguros_Empresas_Otras_Consultas | E33: voz | F33: 3 | G33: 2 | H33: 0 | I33: 0.5 | J33: 0.0028819444 | K33: =INT(Regiones[[#This Row],[Fecha]]) -> 46204 | L33: =IFERROR(Regiones[[#This Row],[Contestadas]]/Regiones[[#This Row],[Ofrecidas]],"") -> 0.66666667 | M33: =IFERROR(Regiones[[#This Row],[Ofrecidas]]*Regiones[[#This Row],[% de nivel de servicio]],"") -> 1.5 | O33: =IFERROR(Regiones[[#This Row],[Aten < 20 seg]]/Regiones[[#This Row],[Contestadas]],"") -> 0.75 | P33: =IFERROR(Regiones[[#This Row],[AHT]]*86400,"error") -> 249 | Q33: =+VLOOKUP(Regiones[[#This Row],[Cola]],Tabla6[#Data],2,0) -> BUPA | R33: =+VLOOKUP(Regiones[[#This Row],[Cola]],Tabla68[],2,0) -> #N/A
B34: 46204 | C34: 0.45833333 | D34: BUPA_Servicio_al_Cliente_Nacional | E34: voz | F34: 4 | G34: 3 | H34: 2 | I34: 0 | J34: 0.0070833333 | K34: =INT(Regiones[[#This Row],[Fecha]]) -> 46204 | L34: =IFERROR(Regiones[[#This Row],[Contestadas]]/Regiones[[#This Row],[Ofrecidas]],"") -> 0.75 | M34: =IFERROR(Regiones[[#This Row],[Ofrecidas]]*Regiones[[#This Row],[% de nivel de servicio]],"") -> 0 | O34: =IFERROR(Regiones[[#This Row],[Aten < 20 seg]]/Regiones[[#This Row],[Contestadas]],"") -> 0 | P34: =IFERROR(Regiones[[#This Row],[AHT]]*86400,"error") -> 612 | Q34: =+VLOOKUP(Regiones[[#This Row],[Cola]],Tabla6[#Data],2,0) -> BUPA | R34: =+VLOOKUP(Regiones[[#This Row],[Cola]],Tabla68[],2,0) -> #N/A
B35: 46204 | C35: 0.45833333 | D35: BUPA_Seguro_Colectivo_Representante | E35: voz | F35: 0 | G35: 0 | H35: 1 | I35: 0 | J35: None | K35: =INT(Regiones[[#This Row],[Fecha]]) -> 46204 | L35: =IFERROR(Regiones[[#This Row],[Contestadas]]/Regiones[[#This Row],[Ofrecidas]],"") | M35: =IFERROR(Regiones[[#This Row],[Ofrecidas]]*Regiones[[#This Row],[% de nivel de servicio]],"") -> 0 | O35: =IFERROR(Regiones[[#This Row],[Aten < 20 seg]]/Regiones[[#This Row],[Contestadas]],"") | P35: =IFERROR(Regiones[[#This Row],[AHT]]*86400,"error") -> error | Q35: =+VLOOKUP(Regiones[[#This Row],[Cola]],Tabla6[#Data],2,0) -> BUPA | R35: =+VLOOKUP(Regiones[[#This Row],[Cola]],Tabla68[],2,0) -> #N/A
B36: 46204 | C36: 0.45833333 | D36: BUPA_Otras_Consultas | E36: voz | F36: 19 | G36: 21 | H36: 1 | I36: 0.09 | J36: 0.0044097222 | K36: =INT(Regiones[[#This Row],[Fecha]]) -> 46204 | L36: =IFERROR(Regiones[[#This Row],[Contestadas]]/Regiones[[#This Row],[Ofrecidas]],"") -> 1.1052632 | M36: =IFERROR(Regiones[[#This Row],[Ofrecidas]]*Regiones[[#This Row],[% de nivel de servicio]],"") -> 1.71 | O36: =IFERROR(Regiones[[#This Row],[Aten < 20 seg]]/Regiones[[#This Row],[Contestadas]],"") -> 0.081428571 | P36: =IFERROR(Regiones[[#This Row],[AHT]]*86400,"error") -> 381 | Q36: =+VLOOKUP(Regiones[[#This Row],[Cola]],Tabla6[#Data],2,0) -> BUPA | R36: =+VLOOKUP(Regiones[[#This Row],[Cola]],Tabla68[],2,0) -> #N/A
B37: 46204 | C37: 0.45833333 | D37: BUPA_Consulta_Liquidacion_Reembolso | E37: voz | F37: 2 | G37: 2 | H37: 1 | I37: 0 | J37: 0.0059606481 | K37: =INT(Regiones[[#This Row],[Fecha]]) -> 46204 | L37: =IFERROR(Regiones[[#This Row],[Contestadas]]/Regiones[[#This Row],[Ofrecidas]],"") -> 1 | M37: =IFERROR(Regiones[[#This Row],[Ofrecidas]]*Regiones[[#This Row],[% de nivel de servicio]],"") -> 0 | O37: =IFERROR(Regiones[[#This Row],[Aten < 20 seg]]/Regiones[[#This Row],[Contestadas]],"") -> 0 | P37: =IFERROR(Regiones[[#This Row],[AHT]]*86400,"error") -> 515 | Q37: =+VLOOKUP(Regiones[[#This Row],[Cola]],Tabla6[#Data],2,0) -> BUPA | R37: =+VLOOKUP(Regiones[[#This Row],[Cola]],Tabla68[],2,0) -> #N/A
B38: 46204 | C38: 0.45833333 | D38: BUPA_Cambio_medio_de_pago | E38: voz | F38: 1 | G38: 1 | H38: 0 | I38: 0 | J38: 0.0023148148 | K38: =INT(Regiones[[#This Row],[Fecha]]) -> 46204 | L38: =IFERROR(Regiones[[#This Row],[Contestadas]]/Regiones[[#This Row],[Ofrecidas]],"") -> 1 | M38: =IFERROR(Regiones[[#This Row],[Ofrecidas]]*Regiones[[#This Row],[% de nivel de servicio]],"") -> 0 | O38: =IFERROR(Regiones[[#This Row],[Aten < 20 seg]]/Regiones[[#This Row],[Contestadas]],"") -> 0 | P38: =IFERROR(Regiones[[#This Row],[AHT]]*86400,"error") -> 200 | Q38: =+VLOOKUP(Regiones[[#This Row],[Cola]],Tabla6[#Data],2,0) -> BUPA | R38: =+VLOOKUP(Regiones[[#This Row],[Cola]],Tabla68[],2,0) -> #N/A
B39: 46204 | C39: 0.45833333 | D39: BUPA_Consultas_Cobertura | E39: voz | F39: 2 | G39: 1 | H39: 0 | I39: 0 | J39: 0.0059722222 | K39: =INT(Regiones[[#This Row],[Fecha]]) -> 46204 | L39: =IFERROR(Regiones[[#This Row],[Contestadas]]/Regiones[[#This Row],[Ofrecidas]],"") -> 0.5 | M39: =IFERROR(Regiones[[#This Row],[Ofrecidas]]*Regiones[[#This Row],[% de nivel de servicio]],"") -> 0 | O39: =IFERROR(Regiones[[#This Row],[Aten < 20 seg]]/Regiones[[#This Row],[Contestadas]],"") -> 0 | P39: =IFERROR(Regiones[[#This Row],[AHT]]*86400,"error") -> 516 | Q39: =+VLOOKUP(Regiones[[#This Row],[Cola]],Tabla6[#Data],2,0) -> BUPA | R39: =+VLOOKUP(Regiones[[#This Row],[Cola]],Tabla68[],2,0) -> #N/A
B40: 46204 | C40: 0.45833333 | D40: BUPA_Reembolsos | E40: voz | F40: 8 | G40: 6 | H40: 2 | I40: 0.12 | J40: 0.0080902778 | K40: =INT(Regiones[[#This Row],[Fecha]]) -> 46204 | L40: =IFERROR(Regiones[[#This Row],[Contestadas]]/Regiones[[#This Row],[Ofrecidas]],"") -> 0.75 | M40: =IFERROR(Regiones[[#This Row],[Ofrecidas]]*Regiones[[#This Row],[% de nivel de servicio]],"") -> 0.96 | O40: =IFERROR(Regiones[[#This Row],[Aten < 20 seg]]/Regiones[[#This Row],[Contestadas]],"") -> 0.16 | P40: =IFERROR(Regiones[[#This Row],[AHT]]*86400,"error") -> 699 | Q40: =+VLOOKUP(Regiones[[#This Row],[Cola]],Tabla6[#Data],2,0) -> BUPA | R40: =+VLOOKUP(Regiones[[#This Row],[Cola]],Tabla68[],2,0) -> #N/A
B41: 46204 | C41: 0.45833333 | D41: BUPA_Cobros | E41: voz | F41: 4 | G41: 3 | H41: 0 | I41: 0.33 | J41: 0.0082523148 | K41: =INT(Regiones[[#This Row],[Fecha]]) -> 46204 | L41: =IFERROR(Regiones[[#This Row],[Contestadas]]/Regiones[[#This Row],[Ofrecidas]],"") -> 0.75 | M41: =IFERROR(Regiones[[#This Row],[Ofrecidas]]*Regiones[[#This Row],[% de nivel de servicio]],"") -> 1.32 | O41: =IFERROR(Regiones[[#This Row],[Aten < 20 seg]]/Regiones[[#This Row],[Contestadas]],"") -> 0.44 | P41: =IFERROR(Regiones[[#This Row],[AHT]]*86400,"error") -> 713 | Q41: =+VLOOKUP(Regiones[[#This Row],[Cola]],Tabla6[#Data],2,0) -> BUPA | R41: =+VLOOKUP(Regiones[[#This Row],[Cola]],Tabla68[],2,0) -> #N/A
...

Sheet BUPA Seguros
X2: Ingresar Fecha a revisar
L3: BUPA | W3: FECHA | X3: 46209 | AS3: 1 | AT3: 6 | AU3: 15
L4: DIA | M4: Forecast | N4: Recibidas | O4: Desv | P4: Llam At | Q4: Ate <20 | R4: Abandono | S4: % Abandono | T4: NDS | U4: NDA | W4: INTERVALO | X4: RECIBIDAS | Y4: FORECAST | Z4: ATENDIDAS | AA4: ABANDONO | AB4: < 20 Seg | AS4: {=SUMPRODUCT(_xlfn.CHOOSECOLS(_xlfn._xlws.FILTER(_xlfn.CHOOSECOLS(Regiones[#Data],1,6,15),_xlfn.CHOOSECOLS(_xlfn.CHOOSECOLS(Regiones[#Data],1,6,15),1)=L7),2),_xlfn.CHOOSECOLS(_xlfn._xlws.FILTER(_xlfn.CHOOSECOLS(Regiones[#Data],1,6,15),_xlfn.CHOOSECOLS(_xlfn.CHOOSECOLS(Regiones[#Data],1,6,15),1)=L7),3)/SUM(_xlfn.CHOOSECOLS(_xlfn._xlws.FILTER(_xlfn.CHOOSECOLS(Regiones[#Data],1,6,15),_xlfn.CHOOSECOLS(_xlfn.CHOOSECOLS(Regiones[#Data],1,6,15),1)=L7),2)))} -> #VALUE!
B5: Fecha | C5: Intervalo | D5: Recibidas | E5: Atendidas | F5: Forecast | G5: TMO | H5: NS | I5: NA | L5: 46204 | M5: =+SUMIFS(Tabla54[Forecast],Tabla54[Fecha],$L5) -> 664.4631 | N5: =+SUMIFS(Regiones[Ofrecidas],Regiones[Fecha2],'BUPA Seguros'!$L5,Regiones[Skill],'BUPA Seguros'!$L$3) -> 687 | O5: =N5/M5-1 -> 0.033917457 | P5: =+SUMIFS(Regiones[Contestadas],Regiones[Fecha2],'BUPA Seguros'!$L5,Regiones[Skill],'BUPA Seguros'!$L$3) -> 614 | Q5: =+SUMIFS(Regiones[Aten < 20 seg],Regiones[Fecha2],'BUPA Seguros'!$L5,Regiones[Skill],'BUPA Seguros'!$L$3) -> 307.91 | R5: =+N5-P5 -> 73 | S5: =IFERROR(R5/N5,"") -> 0.1062591 | T5: =IFERROR(Q5/N5,"") -> 0.44819505 | U5: =IFERROR(P5/N5,"") -> 0.8937409 | W5: 0.27083333 | X5: =+SUMIFS(Tabla54[Recibidas],Tabla54[Fecha],$X$3,Tabla54[Intervalo],$W5) -> 0 | Y5: =+SUMIFS(Tabla54[Forecast],Tabla54[Fecha],$X$3,Tabla54[Intervalo],$W5) -> 0 | Z5: =+SUMIFS(Tabla54[Atendidas],Tabla54[Fecha],$X$3,Tabla54[Intervalo],$W5) -> 0 | AA5: =+X5-Z5 -> 0 | AB5: =+SUMIFS(Regiones[Aten < 20 seg],Regiones[Fecha],'BUPA Seguros'!$X$3,Regiones[Intervalo],'BUPA Seguros'!$W5,Regiones[Skill],'BUPA Seguros'!$L$3) -> 0 | AS5: {=SUMPRODUCT(_xlfn.CHOOSECOLS(_xlfn._xlws.FILTER(_xlfn.CHOOSECOLS(Regiones[#Data],1,6,15),_xlfn.CHOOSECOLS(_xlfn.CHOOSECOLS(Regiones[#Data],1,6,15),1)=L8),2),_xlfn.CHOOSECOLS(_xlfn._xlws.FILTER(_xlfn.CHOOSECOLS(Regiones[#Data],1,6,15),_xlfn.CHOOSECOLS(_xlfn.CHOOSECOLS(Regiones[#Data],1,6,15),1)=L8),3)/SUM(_xlfn.CHOOSECOLS(_xlfn._xlws.FILTER(_xlfn.CHOOSECOLS(Regiones[#Data],1,6,15),_xlfn.CHOOSECOLS(_xlfn.CHOOSECOLS(Regiones[#Data],1,6,15),1)=L8),2)))} -> #VALUE!
B6: 46204 | C6: 0 | D6: =+SUMIFS(Regiones[Ofrecidas],Regiones[Fecha],Tabla54[[#This Row],[Fecha]],Regiones[Intervalo],Tabla54[[#This Row],[Intervalo]],Regiones[Skill],'BUPA Seguros'!$L$3) -> 0 | E6: =+SUMIFS(Regiones[Contestadas],Regiones[Fecha],Tabla54[[#This Row],[Fecha]],Regiones[Intervalo],Tabla54[[#This Row],[Intervalo]],Regiones[Skill],'BUPA Seguros'!$L$3) -> 0 | F6: 0 | G6: =IFERROR(SUMIFS(Regiones[TMO],Regiones[Fecha],Tabla54[[#This Row],[Fecha]],Regiones[Intervalo],Tabla54[[#This Row],[Intervalo]],Regiones[Skill],'BUPA Seguros'!$L$3)/Tabla54[[#This Row],[Atendidas]],0) -> 0 | H6: =IFERROR(SUMIFS(Regiones[Aten < 20 seg],Regiones[Fecha],Tabla54[[#This Row],[Fecha]],Regiones[Intervalo],Tabla54[[#This Row],[Intervalo]],Regiones[Skill],'BUPA Seguros'!$L$3)/Tabla54[[#This Row],[Recibidas]],0) -> 0 | I6: =IFERROR(Tabla54[[#This Row],[Atendidas]]/Tabla54[[#This Row],[Recibidas]],0) -> 0 | L6: =+L5+1 -> 46205 | M6: =+SUMIFS(Tabla54[Forecast],Tabla54[Fecha],$L6) -> 496.21216 | N6: =+SUMIFS(Regiones[Ofrecidas],Regiones[Fecha2],'BUPA Seguros'!$L6,Regiones[Skill],'BUPA Seguros'!$L$3) -> 576 | O6: =N6/M6-1 -> 0.1607938 | P6: =+SUMIFS(Regiones[Contestadas],Regiones[Fecha2],'BUPA Seguros'!$L6,Regiones[Skill],'BUPA Seguros'!$L$3) -> 529 | Q6: =+SUMIFS(Regiones[Aten < 20 seg],Regiones[Fecha2],'BUPA Seguros'!$L6,Regiones[Skill],'BUPA Seguros'!$L$3) -> 342.95 | R6: =+N6-P6 -> 47 | S6: =IFERROR(R6/N6,"") -> 0.081597222 | T6: =IFERROR(Q6/N6,"") -> 0.59539931 | U6: =IFERROR(P6/N6,"") -> 0.91840278 | W6: 0.29166667 | X6: =+SUMIFS(Tabla54[Recibidas],Tabla54[Fecha],$X$3,Tabla54[Intervalo],$W6) -> 0 | Y6: =+SUMIFS(Tabla54[Forecast],Tabla54[Fecha],$X$3,Tabla54[Intervalo],$W6) -> 0 | Z6: =+SUMIFS(Tabla54[Atendidas],Tabla54[Fecha],$X$3,Tabla54[Intervalo],$W6) -> 0 | AA6: =+X6-Z6 -> 0 | AB6: =+SUMIFS(Regiones[Aten < 20 seg],Regiones[Fecha],'BUPA Seguros'!$X$3,Regiones[Intervalo],'BUPA Seguros'!$W6,Regiones[Skill],'BUPA Seguros'!$L$3) -> 0
B7: =+B6 -> 46204 | C7: 0.020833333 | D7: =+SUMIFS(Regiones[Ofrecidas],Regiones[Fecha],Tabla54[[#This Row],[Fecha]],Regiones[Intervalo],Tabla54[[#This Row],[Intervalo]],Regiones[Skill],'BUPA Seguros'!$L$3) -> 0 | E7: =+SUMIFS(Regiones[Contestadas],Regiones[Fecha],Tabla54[[#This Row],[Fecha]],Regiones[Intervalo],Tabla54[[#This Row],[Intervalo]],Regiones[Skill],'BUPA Seguros'!$L$3) -> 0 | F7: 0 | G7: =IFERROR(SUMIFS(Regiones[TMO],Regiones[Fecha],Tabla54[[#This Row],[Fecha]],Regiones[Intervalo],Tabla54[[#This Row],[Intervalo]],Regiones[Skill],'BUPA Seguros'!$L$3)/Tabla54[[#This Row],[Atendidas]],0) -> 0 | H7: =IFERROR(SUMIFS(Regiones[Aten < 20 seg],Regiones[Fecha],Tabla54[[#This Row],[Fecha]],Regiones[Intervalo],Tabla54[[#This Row],[Intervalo]],Regiones[Skill],'BUPA Seguros'!$L$3)/Tabla54[[#This Row],[Recibidas]],0) -> 0 | I7: =IFERROR(Tabla54[[#This Row],[Atendidas]]/Tabla54[[#This Row],[Recibidas]],0) -> 0 | L7: =+L6+1 -> 46206 | M7: =+SUMIFS(Tabla54[Forecast],Tabla54[Fecha],$L7) -> 532.93699 | N7: =+SUMIFS(Regiones[Ofrecidas],Regiones[Fecha2],'BUPA Seguros'!$L7,Regiones[Skill],'BUPA Seguros'!$L$3) -> 525 | O7: =N7/M7-1 -> -0.014892917 | P7: =+SUMIFS(Regiones[Contestadas],Regiones[Fecha2],'BUPA Seguros'!$L7,Regiones[Skill],'BUPA Seguros'!$L$3) -> 485 | Q7: =+SUMIFS(Regiones[Aten < 20 seg],Regiones[Fecha2],'BUPA Seguros'!$L7,Regiones[Skill],'BUPA Seguros'!$L$3) -> 292.27 | R7: =+N7-P7 -> 40 | S7: =IFERROR(R7/N7,"") -> 0.076190476 | T7: =IFERROR(Q7/N7,"") -> 0.55670476 | U7: =IFERROR(P7/N7,"") -> 0.92380952 | W7: 0.3125 | X7: =+SUMIFS(Tabla54[Recibidas],Tabla54[Fecha],$X$3,Tabla54[Intervalo],$W7) -> 0 | Y7: =+SUMIFS(Tabla54[Forecast],Tabla54[Fecha],$X$3,Tabla54[Intervalo],$W7) -> 0 | Z7: =+SUMIFS(Tabla54[Atendidas],Tabla54[Fecha],$X$3,Tabla54[Intervalo],$W7) -> 0 | AA7: =+X7-Z7 -> 0 | AB7: =+SUMIFS(Regiones[Aten < 20 seg],Regiones[Fecha],'BUPA Seguros'!$X$3,Regiones[Intervalo],'BUPA Seguros'!$W7,Regiones[Skill],'BUPA Seguros'!$L$3) -> 0 | AN7: Nivel Servicio | AO7: =+SUM(AB5:AB32)/SUM(X5:X32) -> #DIV/0! | AR7: =+AS7/86400 -> 0.0043830661 | AS7: {=SUMPRODUCT(_xlfn.CHOOSECOLS(_xlfn._xlws.FILTER(_xlfn.CHOOSECOLS(Regiones[#Data],1,6,15,16),(_xlfn.CHOOSECOLS(_xlfn.CHOOSECOLS(Regiones[#Data],1,6,15,16),1)=L7)*(_xlfn.CHOOSECOLS(_xlfn.CHOOSECOLS(Regiones[#Data],1,6,15,16),4)=$L$3)),2),_xlfn.CHOOSECOLS(_xlfn._xlws.FILTER(_xlfn.CHOOSECOLS(Regiones[#Data],1,6,15,16),(_xlfn.CHOOSECOLS(_xlfn.CHOOSECOLS(Regiones[#Data],1,6,15,16),1)=L7)*(_xlfn.CHOOSECOLS(_xlfn.CHOOSECOLS(Regiones[#Data],1,6,15,16),4)=$L$3)),3))/SUM(_xlfn.CHOOSECOLS(_xlfn._xlws.FILTER(_xlfn.CHOOSECOLS(Regiones[#Data],1,6,15,16),(_xlfn.CHOOSECOLS(_xlfn.CHOOSECOLS(Regiones[#Data],1,6,15,16),1)=L7)*(_xlfn.CHOOSECOLS(_xlfn.CHOOSECOLS(Regiones[#Data],1,6,15,16),4)=$L$3)),2))} -> 378.69691 | AT7: quitar TMO con error y llamadas
B8: =+B7 -> 46204 | C8: 0.041666667 | D8: =+SUMIFS(Regiones[Ofrecidas],Regiones[Fecha],Tabla54[[#This Row],[Fecha]],Regiones[Intervalo],Tabla54[[#This Row],[Intervalo]],Regiones[Skill],'BUPA Seguros'!$L$3) -> 0 | E8: =+SUMIFS(Regiones[Contestadas],Regiones[Fecha],Tabla54[[#This Row],[Fecha]],Regiones[Intervalo],Tabla54[[#This Row],[Intervalo]],Regiones[Skill],'BUPA Seguros'!$L$3) -> 0 | F8: 0 | G8: =IFERROR(SUMIFS(Regiones[TMO],Regiones[Fecha],Tabla54[[#This Row],[Fecha]],Regiones[Intervalo],Tabla54[[#This Row],[Intervalo]],Regiones[Skill],'BUPA Seguros'!$L$3)/Tabla54[[#This Row],[Atendidas]],0) -> 0 | H8: =IFERROR(SUMIFS(Regiones[Aten < 20 seg],Regiones[Fecha],Tabla54[[#This Row],[Fecha]],Regiones[Intervalo],Tabla54[[#This Row],[Intervalo]],Regiones[Skill],'BUPA Seguros'!$L$3)/Tabla54[[#This Row],[Recibidas]],0) -> 0 | I8: =IFERROR(Tabla54[[#This Row],[Atendidas]]/Tabla54[[#This Row],[Recibidas]],0) -> 0 | L8: =+L7+1 -> 46207 | M8: =+SUMIFS(Tabla54[Forecast],Tabla54[Fecha],$L8) -> 0 | N8: 0 | P8: =+SUMIFS(Regiones[Contestadas],Regiones[Fecha2],'BUPA Seguros'!$L8,Regiones[Skill],'BUPA Seguros'!$L$3) -> 0 | Q8: =+SUMIFS(Regiones[Aten < 20 seg],Regiones[Fecha2],'BUPA Seguros'!$L8,Regiones[Skill],'BUPA Seguros'!$L$3) -> 0 | R8: =+N8-P8 -> 0 | S8: =IFERROR(R8/N8,"") | T8: =IFERROR(Q8/N8,"") | U8: =IFERROR(P8/N8,"") | W8: 0.33333333 | X8: =+SUMIFS(Tabla54[Recibidas],Tabla54[Fecha],$X$3,Tabla54[Intervalo],$W8) -> 0 | Y8: =+SUMIFS(Tabla54[Forecast],Tabla54[Fecha],$X$3,Tabla54[Intervalo],$W8) -> 0 | Z8: =+SUMIFS(Tabla54[Atendidas],Tabla54[Fecha],$X$3,Tabla54[Intervalo],$W8) -> 0 | AA8: =+X8-Z8 -> 0 | AB8: =+SUMIFS(Regiones[Aten < 20 seg],Regiones[Fecha],'BUPA Seguros'!$X$3,Regiones[Intervalo],'BUPA Seguros'!$W8,Regiones[Skill],'BUPA Seguros'!$L$3) -> 0 | AN8: Nivel Atencion | AO8: =+SUM(Z5:Z32)/SUM(X5:X32) -> #DIV/0! | AR8: =+AS8/86400 -> #DIV/0! | AS8: {=SUMPRODUCT(_xlfn.CHOOSECOLS(_xlfn._xlws.FILTER(_xlfn.CHOOSECOLS(Regiones[#Data],1,6,15,16),(_xlfn.CHOOSECOLS(_xlfn.CHOOSECOLS(Regiones[#Data],1,6,15,16),1)=L8)*(_xlfn.CHOOSECOLS(_xlfn.CHOOSECOLS(Regiones[#Data],1,6,15,16),4)=$L$3)),2),_xlfn.CHOOSECOLS(_xlfn._xlws.FILTER(_xlfn.CHOOSECOLS(Regiones[#Data],1,6,15,16),(_xlfn.CHOOSECOLS(_xlfn.CHOOSECOLS(Regiones[#Data],1,6,15,16),1)=L8)*(_xlfn.CHOOSECOLS(_xlfn.CHOOSECOLS(Regiones[#Data],1,6,15,16),4)=$L$3)),3))/SUM(_xlfn.CHOOSECOLS(_xlfn._xlws.FILTER(_xlfn.CHOOSECOLS(Regiones[#Data],1,6,15,16),(_xlfn.CHOOSECOLS(_xlfn.CHOOSECOLS(Regiones[#Data],1,6,15,16),1)=L8)*(_xlfn.CHOOSECOLS(_xlfn.CHOOSECOLS(Regiones[#Data],1,6,15,16),4)=$L$3)),2))} -> #DIV/0!
B9: =+B8 -> 46204 | C9: 0.0625 | D9: =+SUMIFS(Regiones[Ofrecidas],Regiones[Fecha],Tabla54[[#This Row],[Fecha]],Regiones[Intervalo],Tabla54[[#This Row],[Intervalo]],Regiones[Skill],'BUPA Seguros'!$L$3) -> 0 | E9: =+SUMIFS(Regiones[Contestadas],Regiones[Fecha],Tabla54[[#This Row],[Fecha]],Regiones[Intervalo],Tabla54[[#This Row],[Intervalo]],Regiones[Skill],'BUPA Seguros'!$L$3) -> 0 | F9: 0 | G9: =IFERROR(SUMIFS(Regiones[TMO],Regiones[Fecha],Tabla54[[#This Row],[Fecha]],Regiones[Intervalo],Tabla54[[#This Row],[Intervalo]],Regiones[Skill],'BUPA Seguros'!$L$3)/Tabla54[[#This Row],[Atendidas]],0) -> 0 | H9: =IFERROR(SUMIFS(Regiones[Aten < 20 seg],Regiones[Fecha],Tabla54[[#This Row],[Fecha]],Regiones[Intervalo],Tabla54[[#This Row],[Intervalo]],Regiones[Skill],'BUPA Seguros'!$L$3)/Tabla54[[#This Row],[Recibidas]],0) -> 0 | I9: =IFERROR(Tabla54[[#This Row],[Atendidas]]/Tabla54[[#This Row],[Recibidas]],0) -> 0 | L9: =+L8+1 -> 46208 | M9: =+SUMIFS(Tabla54[Forecast],Tabla54[Fecha],$L9) -> 0 | N9: =+SUMIFS(Regiones[Ofrecidas],Regiones[Fecha2],'BUPA Seguros'!$L9,Regiones[Skill],'BUPA Seguros'!$L$3) -> 0 | P9: =+SUMIFS(Regiones[Contestadas],Regiones[Fecha2],'BUPA Seguros'!$L9,Regiones[Skill],'BUPA Seguros'!$L$3) -> 0 | Q9: =+SUMIFS(Regiones[Aten < 20 seg],Regiones[Fecha2],'BUPA Seguros'!$L9,Regiones[Skill],'BUPA Seguros'!$L$3) -> 0 | R9: =+N9-P9 -> 0 | S9: =IFERROR(R9/N9,"") | T9: =IFERROR(Q9/N9,"") | U9: =IFERROR(P9/N9,"") | W9: 0.35416667 | X9: =+SUMIFS(Tabla54[Recibidas],Tabla54[Fecha],$X$3,Tabla54[Intervalo],$W9) -> 0 | Y9: =+SUMIFS(Tabla54[Forecast],Tabla54[Fecha],$X$3,Tabla54[Intervalo],$W9) -> 0 | Z9: =+SUMIFS(Tabla54[Atendidas],Tabla54[Fecha],$X$3,Tabla54[Intervalo],$W9) -> 0 | AA9: =+X9-Z9 -> 0 | AB9: =+SUMIFS(Regiones[Aten < 20 seg],Regiones[Fecha],'BUPA Seguros'!$X$3,Regiones[Intervalo],'BUPA Seguros'!$W9,Regiones[Skill],'BUPA Seguros'!$L$3) -> 0 | AR9: =+AS9/86400 -> #VALUE! | AS9: {=SUMPRODUCT(_xlfn.CHOOSECOLS(_xlfn._xlws.FILTER(_xlfn.CHOOSECOLS(Regiones[#Data],1,6,15,16),(_xlfn.CHOOSECOLS(_xlfn.CHOOSECOLS(Regiones[#Data],1,6,15,16),1)=L9)*(_xlfn.CHOOSECOLS(_xlfn.CHOOSECOLS(Regiones[#Data],1,6,15,16),4)=$L$3)),2),_xlfn.CHOOSECOLS(_xlfn._xlws.FILTER(_xlfn.CHOOSECOLS(Regiones[#Data],1,6,15,16),(_xlfn.CHOOSECOLS(_xlfn.CHOOSECOLS(Regiones[#Data],1,6,15,16),1)=L9)*(_xlfn.CHOOSECOLS(_xlfn.CHOOSECOLS(Regiones[#Data],1,6,15,16),4)=$L$3)),3))/SUM(_xlfn.CHOOSECOLS(_xlfn._xlws.FILTER(_xlfn.CHOOSECOLS(Regiones[#Data],1,6,15,16),(_xlfn.CHOOSECOLS(_xlfn.CHOOSECOLS(Regiones[#Data],1,6,15,16),1)=L9)*(_xlfn.CHOOSECOLS(_xlfn.CHOOSECOLS(Regiones[#Data],1,6,15,16),4)=$L$3)),2))} -> #VALUE!
B10: =+B9 -> 46204 | C10: 0.083333333 | D10: =+SUMIFS(Regiones[Ofrecidas],Regiones[Fecha],Tabla54[[#This Row],[Fecha]],Regiones[Intervalo],Tabla54[[#This Row],[Intervalo]],Regiones[Skill],'BUPA Seguros'!$L$3) -> 0 | E10: =+SUMIFS(Regiones[Contestadas],Regiones[Fecha],Tabla54[[#This Row],[Fecha]],Regiones[Intervalo],Tabla54[[#This Row],[Intervalo]],Regiones[Skill],'BUPA Seguros'!$L$3) -> 0 | F10: 0 | G10: =IFERROR(SUMIFS(Regiones[TMO],Regiones[Fecha],Tabla54[[#This Row],[Fecha]],Regiones[Intervalo],Tabla54[[#This Row],[Intervalo]],Regiones[Skill],'BUPA Seguros'!$L$3)/Tabla54[[#This Row],[Atendidas]],0) -> 0 | H10: =IFERROR(SUMIFS(Regiones[Aten < 20 seg],Regiones[Fecha],Tabla54[[#This Row],[Fecha]],Regiones[Intervalo],Tabla54[[#This Row],[Intervalo]],Regiones[Skill],'BUPA Seguros'!$L$3)/Tabla54[[#This Row],[Recibidas]],0) -> 0 | I10: =IFERROR(Tabla54[[#This Row],[Atendidas]]/Tabla54[[#This Row],[Recibidas]],0) -> 0 | L10: =+L9+1 -> 46209 | M10: =+SUMIFS(Tabla54[Forecast],Tabla54[Fecha],$L10) -> 829.29778 | N10: 720 | O10: =N10/M10-1 -> -0.13179558 | P10: 559 | Q10: 146 | R10: =+N10-P10 -> 161 | S10: =IFERROR(R10/N10,"") -> 0.22361111 | T10: =IFERROR(Q10/N10,"") -> 0.20277778 | U10: =IFERROR(P10/N10,"") -> 0.77638889 | W10: 0.375 | X10: =+SUMIFS(Tabla54[Recibidas],Tabla54[Fecha],$X$3,Tabla54[Intervalo],$W10) -> 0 | Y10: =+SUMIFS(Tabla54[Forecast],Tabla54[Fecha],$X$3,Tabla54[Intervalo],$W10) -> 51.985086 | Z10: =+SUMIFS(Tabla54[Atendidas],Tabla54[Fecha],$X$3,Tabla54[Intervalo],$W10) -> 0 | AA10: =+X10-Z10 -> 0 | AB10: =+SUMIFS(Regiones[Aten < 20 seg],Regiones[Fecha],'BUPA Seguros'!$X$3,Regiones[Intervalo],'BUPA Seguros'!$W10,Regiones[Skill],'BUPA Seguros'!$L$3) -> 0 | AR10: =+AS10/86400 -> #VALUE! | AS10: {=SUMPRODUCT(_xlfn.CHOOSECOLS(_xlfn._xlws.FILTER(_xlfn.CHOOSECOLS(Regiones[#Data],1,6,15,16),(_xlfn.CHOOSECOLS(_xlfn.CHOOSECOLS(Regiones[#Data],1,6,15,16),1)=L10)*(_xlfn.CHOOSECOLS(_xlfn.CHOOSECOLS(Regiones[#Data],1,6,15,16),4)=$L$3)),2),_xlfn.CHOOSECOLS(_xlfn._xlws.FILTER(_xlfn.CHOOSECOLS(Regiones[#Data],1,6,15,16),(_xlfn.CHOOSECOLS(_xlfn.CHOOSECOLS(Regiones[#Data],1,6,15,16),1)=L10)*(_xlfn.CHOOSECOLS(_xlfn.CHOOSECOLS(Regiones[#Data],1,6,15,16),4)=$L$3)),3))/SUM(_xlfn.CHOOSECOLS(_xlfn._xlws.FILTER(_xlfn.CHOOSECOLS(Regiones[#Data],1,6,15,16),(_xlfn.CHOOSECOLS(_xlfn.CHOOSECOLS(Regiones[#Data],1,6,15,16),1)=L10)*(_xlfn.CHOOSECOLS(_xlfn.CHOOSECOLS(Regiones[#Data],1,6,15,16),4)=$L$3)),2))} -> #VALUE!
B11: =+B10 -> 46204 | C11: 0.10416667 | D11: =+SUMIFS(Regiones[Ofrecidas],Regiones[Fecha],Tabla54[[#This Row],[Fecha]],Regiones[Intervalo],Tabla54[[#This Row],[Intervalo]],Regiones[Skill],'BUPA Seguros'!$L$3) -> 0 | E11: =+SUMIFS(Regiones[Contestadas],Regiones[Fecha],Tabla54[[#This Row],[Fecha]],Regiones[Intervalo],Tabla54[[#This Row],[Intervalo]],Regiones[Skill],'BUPA Seguros'!$L$3) -> 0 | F11: 0 | G11: =IFERROR(SUMIFS(Regiones[TMO],Regiones[Fecha],Tabla54[[#This Row],[Fecha]],Regiones[Intervalo],Tabla54[[#This Row],[Intervalo]],Regiones[Skill],'BUPA Seguros'!$L$3)/Tabla54[[#This Row],[Atendidas]],0) -> 0 | H11: =IFERROR(SUMIFS(Regiones[Aten < 20 seg],Regiones[Fecha],Tabla54[[#This Row],[Fecha]],Regiones[Intervalo],Tabla54[[#This Row],[Intervalo]],Regiones[Skill],'BUPA Seguros'!$L$3)/Tabla54[[#This Row],[Recibidas]],0) -> 0 | I11: =IFERROR(Tabla54[[#This Row],[Atendidas]]/Tabla54[[#This Row],[Recibidas]],0) -> 0 | L11: =+L10+1 -> 46210 | M11: =+SUMIFS(Tabla54[Forecast],Tabla54[Fecha],$L11) -> 712.29078 | N11: =+SUMIFS(Regiones[Ofrecidas],Regiones[Fecha2],'BUPA Seguros'!$L11,Regiones[Skill],'BUPA Seguros'!$L$3) -> 0 | P11: =+SUMIFS(Regiones[Contestadas],Regiones[Fecha2],'BUPA Seguros'!$L11,Regiones[Skill],'BUPA Seguros'!$L$3) -> 0 | Q11: =+SUMIFS(Regiones[Aten < 20 seg],Regiones[Fecha2],'BUPA Seguros'!$L11,Regiones[Skill],'BUPA Seguros'!$L$3) -> 0 | R11: =+N11-P11 -> 0 | S11: =IFERROR(R11/N11,"") | T11: =IFERROR(Q11/N11,"") | U11: =IFERROR(P11/N11,"") | W11: 0.39583333 | X11: =+SUMIFS(Tabla54[Recibidas],Tabla54[Fecha],$X$3,Tabla54[Intervalo],$W11) -> 0 | Y11: =+SUMIFS(Tabla54[Forecast],Tabla54[Fecha],$X$3,Tabla54[Intervalo],$W11) -> 52.405168 | Z11: =+SUMIFS(Tabla54[Atendidas],Tabla54[Fecha],$X$3,Tabla54[Intervalo],$W11) -> 0 | AA11: =+X11-Z11 -> 0 | AB11: =+SUMIFS(Regiones[Aten < 20 seg],Regiones[Fecha],'BUPA Seguros'!$X$3,Regiones[Intervalo],'BUPA Seguros'!$W11,Regiones[Skill],'BUPA Seguros'!$L$3) -> 0 | AR11: =+AS11/86400 -> #VALUE! | AS11: {=SUMPRODUCT(_xlfn.CHOOSECOLS(_xlfn._xlws.FILTER(_xlfn.CHOOSECOLS(Regiones[#Data],1,6,15,16),(_xlfn.CHOOSECOLS(_xlfn.CHOOSECOLS(Regiones[#Data],1,6,15,16),1)=L11)*(_xlfn.CHOOSECOLS(_xlfn.CHOOSECOLS(Regiones[#Data],1,6,15,16),4)=$L$3)),2),_xlfn.CHOOSECOLS(_xlfn._xlws.FILTER(_xlfn.CHOOSECOLS(Regiones[#Data],1,6,15,16),(_xlfn.CHOOSECOLS(_xlfn.CHOOSECOLS(Regiones[#Data],1,6,15,16),1)=L11)*(_xlfn.CHOOSECOLS(_xlfn.CHOOSECOLS(Regiones[#Data],1,6,15,16),4)=$L$3)),3))/SUM(_xlfn.CHOOSECOLS(_xlfn._xlws.FILTER(_xlfn.CHOOSECOLS(Regiones[#Data],1,6,15,16),(_xlfn.CHOOSECOLS(_xlfn.CHOOSECOLS(Regiones[#Data],1,6,15,16),1)=L11)*(_xlfn.CHOOSECOLS(_xlfn.CHOOSECOLS(Regiones[#Data],1,6,15,16),4)=$L$3)),2))} -> #VALUE!
B12: =+B11 -> 46204 | C12: 0.125 | D12: =+SUMIFS(Regiones[Ofrecidas],Regiones[Fecha],Tabla54[[#This Row],[Fecha]],Regiones[Intervalo],Tabla54[[#This Row],[Intervalo]],Regiones[Skill],'BUPA Seguros'!$L$3) -> 0 | E12: =+SUMIFS(Regiones[Contestadas],Regiones[Fecha],Tabla54[[#This Row],[Fecha]],Regiones[Intervalo],Tabla54[[#This Row],[Intervalo]],Regiones[Skill],'BUPA Seguros'!$L$3) -> 0 | F12: 0 | G12: =IFERROR(SUMIFS(Regiones[TMO],Regiones[Fecha],Tabla54[[#This Row],[Fecha]],Regiones[Intervalo],Tabla54[[#This Row],[Intervalo]],Regiones[Skill],'BUPA Seguros'!$L$3)/Tabla54[[#This Row],[Atendidas]],0) -> 0 | H12: =IFERROR(SUMIFS(Regiones[Aten < 20 seg],Regiones[Fecha],Tabla54[[#This Row],[Fecha]],Regiones[Intervalo],Tabla54[[#This Row],[Intervalo]],Regiones[Skill],'BUPA Seguros'!$L$3)/Tabla54[[#This Row],[Recibidas]],0) -> 0 | I12: =IFERROR(Tabla54[[#This Row],[Atendidas]]/Tabla54[[#This Row],[Recibidas]],0) -> 0 | L12: =+L11+1 -> 46211 | M12: =+SUMIFS(Tabla54[Forecast],Tabla54[Fecha],$L12) -> 568.80775 | N12: =+SUMIFS(Regiones[Ofrecidas],Regiones[Fecha2],'BUPA Seguros'!$L12,Regiones[Skill],'BUPA Seguros'!$L$3) -> 0 | P12: =+SUMIFS(Regiones[Contestadas],Regiones[Fecha2],'BUPA Seguros'!$L12,Regiones[Skill],'BUPA Seguros'!$L$3) -> 0 | Q12: =+SUMIFS(Regiones[Aten < 20 seg],Regiones[Fecha2],'BUPA Seguros'!$L12,Regiones[Skill],'BUPA Seguros'!$L$3) -> 0 | R12: =+N12-P12 -> 0 | S12: =IFERROR(R12/N12,"") | T12: =IFERROR(Q12/N12,"") | U12: =IFERROR(P12/N12,"") | W12: 0.41666667 | X12: =+SUMIFS(Tabla54[Recibidas],Tabla54[Fecha],$X$3,Tabla54[Intervalo],$W12) -> 0 | Y12: =+SUMIFS(Tabla54[Forecast],Tabla54[Fecha],$X$3,Tabla54[Intervalo],$W12) -> 53.429117 | Z12: =+SUMIFS(Tabla54[Atendidas],Tabla54[Fecha],$X$3,Tabla54[Intervalo],$W12) -> 0 | AA12: =+X12-Z12 -> 0 | AB12: =+SUMIFS(Regiones[Aten < 20 seg],Regiones[Fecha],'BUPA Seguros'!$X$3,Regiones[Intervalo],'BUPA Seguros'!$W12,Regiones[Skill],'BUPA Seguros'!$L$3) -> 0 | AR12: =+AS12/86400 -> #VALUE! | AS12: {=SUMPRODUCT(_xlfn.CHOOSECOLS(_xlfn._xlws.FILTER(_xlfn.CHOOSECOLS(Regiones[#Data],1,6,15,16),(_xlfn.CHOOSECOLS(_xlfn.CHOOSECOLS(Regiones[#Data],1,6,15,16),1)=L12)*(_xlfn.CHOOSECOLS(_xlfn.CHOOSECOLS(Regiones[#Data],1,6,15,16),4)=$L$3)),2),_xlfn.CHOOSECOLS(_xlfn._xlws.FILTER(_xlfn.CHOOSECOLS(Regiones[#Data],1,6,15,16),(_xlfn.CHOOSECOLS(_xlfn.CHOOSECOLS(Regiones[#Data],1,6,15,16),1)=L12)*(_xlfn.CHOOSECOLS(_xlfn.CHOOSECOLS(Regiones[#Data],1,6,15,16),4)=$L$3)),3))/SUM(_xlfn.CHOOSECOLS(_xlfn._xlws.FILTER(_xlfn.CHOOSECOLS(Regiones[#Data],1,6,15,16),(_xlfn.CHOOSECOLS(_xlfn.CHOOSECOLS(Regiones[#Data],1,6,15,16),1)=L12)*(_xlfn.CHOOSECOLS(_xlfn.CHOOSECOLS(Regiones[#Data],1,6,15,16),4)=$L$3)),2))} -> #VALUE!
B13: =+B12 -> 46204 | C13: 0.14583333 | D13: =+SUMIFS(Regiones[Ofrecidas],Regiones[Fecha],Tabla54[[#This Row],[Fecha]],Regiones[Intervalo],Tabla54[[#This Row],[Intervalo]],Regiones[Skill],'BUPA Seguros'!$L$3) -> 0 | E13: =+SUMIFS(Regiones[Contestadas],Regiones[Fecha],Tabla54[[#This Row],[Fecha]],Regiones[Intervalo],Tabla54[[#This Row],[Intervalo]],Regiones[Skill],'BUPA Seguros'!$L$3) -> 0 | F13: 0 | G13: =IFERROR(SUMIFS(Regiones[TMO],Regiones[Fecha],Tabla54[[#This Row],[Fecha]],Regiones[Intervalo],Tabla54[[#This Row],[Intervalo]],Regiones[Skill],'BUPA Seguros'!$L$3)/Tabla54[[#This Row],[Atendidas]],0) -> 0 | H13: =IFERROR(SUMIFS(Regiones[Aten < 20 seg],Regiones[Fecha],Tabla54[[#This Row],[Fecha]],Regiones[Intervalo],Tabla54[[#This Row],[Intervalo]],Regiones[Skill],'BUPA Seguros'!$L$3)/Tabla54[[#This Row],[Recibidas]],0) -> 0 | I13: =IFERROR(Tabla54[[#This Row],[Atendidas]]/Tabla54[[#This Row],[Recibidas]],0) -> 0 | L13: =+L12+1 -> 46212 | M13: =+SUMIFS(Tabla54[Forecast],Tabla54[Fecha],$L13) -> 580.76466 | N13: =+SUMIFS(Regiones[Ofrecidas],Regiones[Fecha2],'BUPA Seguros'!$L13,Regiones[Skill],'BUPA Seguros'!$L$3) -> 0 | P13: =+SUMIFS(Regiones[Contestadas],Regiones[Fecha2],'BUPA Seguros'!$L13,Regiones[Skill],'BUPA Seguros'!$L$3) -> 0 | Q13: =+SUMIFS(Regiones[Aten < 20 seg],Regiones[Fecha2],'BUPA Seguros'!$L13,Regiones[Skill],'BUPA Seguros'!$L$3) -> 0 | R13: =+N13-P13 -> 0 | S13: =IFERROR(R13/N13,"") | T13: =IFERROR(Q13/N13,"") | U13: =IFERROR(P13/N13,"") | W13: 0.4375 | X13: =+SUMIFS(Tabla54[Recibidas],Tabla54[Fecha],$X$3,Tabla54[Intervalo],$W13) -> 0 | Y13: =+SUMIFS(Tabla54[Forecast],Tabla54[Fecha],$X$3,Tabla54[Intervalo],$W13) -> 54.78563 | Z13: =+SUMIFS(Tabla54[Atendidas],Tabla54[Fecha],$X$3,Tabla54[Intervalo],$W13) -> 0 | AA13: =+X13-Z13 -> 0 | AB13: =+SUMIFS(Regiones[Aten < 20 seg],Regiones[Fecha],'BUPA Seguros'!$X$3,Regiones[Intervalo],'BUPA Seguros'!$W13,Regiones[Skill],'BUPA Seguros'!$L$3) -> 0
B14: =+B13 -> 46204 | C14: 0.16666667 | D14: =+SUMIFS(Regiones[Ofrecidas],Regiones[Fecha],Tabla54[[#This Row],[Fecha]],Regiones[Intervalo],Tabla54[[#This Row],[Intervalo]],Regiones[Skill],'BUPA Seguros'!$L$3) -> 0 | E14: =+SUMIFS(Regiones[Contestadas],Regiones[Fecha],Tabla54[[#This Row],[Fecha]],Regiones[Intervalo],Tabla54[[#This Row],[Intervalo]],Regiones[Skill],'BUPA Seguros'!$L$3) -> 0 | F14: 0 | G14: =IFERROR(SUMIFS(Regiones[TMO],Regiones[Fecha],Tabla54[[#This Row],[Fecha]],Regiones[Intervalo],Tabla54[[#This Row],[Intervalo]],Regiones[Skill],'BUPA Seguros'!$L$3)/Tabla54[[#This Row],[Atendidas]],0) -> 0 | H14: =IFERROR(SUMIFS(Regiones[Aten < 20 seg],Regiones[Fecha],Tabla54[[#This Row],[Fecha]],Regiones[Intervalo],Tabla54[[#This Row],[Intervalo]],Regiones[Skill],'BUPA Seguros'!$L$3)/Tabla54[[#This Row],[Recibidas]],0) -> 0 | I14: =IFERROR(Tabla54[[#This Row],[Atendidas]]/Tabla54[[#This Row],[Recibidas]],0) -> 0 | L14: =+L13+1 -> 46213 | M14: =+SUMIFS(Tabla54[Forecast],Tabla54[Fecha],$L14) -> 434.71943 | N14: =+SUMIFS(Regiones[Ofrecidas],Regiones[Fecha2],'BUPA Seguros'!$L14,Regiones[Skill],'BUPA Seguros'!$L$3) -> 0 | P14: =+SUMIFS(Regiones[Contestadas],Regiones[Fecha2],'BUPA Seguros'!$L14,Regiones[Skill],'BUPA Seguros'!$L$3) -> 0 | Q14: =+SUMIFS(Regiones[Aten < 20 seg],Regiones[Fecha2],'BUPA Seguros'!$L14,Regiones[Skill],'BUPA Seguros'!$L$3) -> 0 | R14: =+N14-P14 -> 0 | S14: =IFERROR(R14/N14,"") | T14: =IFERROR(Q14/N14,"") | U14: =IFERROR(P14/N14,"") | W14: 0.45833333 | X14: =+SUMIFS(Tabla54[Recibidas],Tabla54[Fecha],$X$3,Tabla54[Intervalo],$W14) -> 0 | Y14: =+SUMIFS(Tabla54[Forecast],Tabla54[Fecha],$X$3,Tabla54[Intervalo],$W14) -> 56.273418 | Z14: =+SUMIFS(Tabla54[Atendidas],Tabla54[Fecha],$X$3,Tabla54[Intervalo],$W14) -> 0 | AA14: =+X14-Z14 -> 0 | AB14: =+SUMIFS(Regiones[Aten < 20 seg],Regiones[Fecha],'BUPA Seguros'!$X$3,Regiones[Intervalo],'BUPA Seguros'!$W14,Regiones[Skill],'BUPA Seguros'!$L$3) -> 0
B15: =+B14 -> 46204 | C15: 0.1875 | D15: =+SUMIFS(Regiones[Ofrecidas],Regiones[Fecha],Tabla54[[#This Row],[Fecha]],Regiones[Intervalo],Tabla54[[#This Row],[Intervalo]],Regiones[Skill],'BUPA Seguros'!$L$3) -> 0 | E15: =+SUMIFS(Regiones[Contestadas],Regiones[Fecha],Tabla54[[#This Row],[Fecha]],Regiones[Intervalo],Tabla54[[#This Row],[Intervalo]],Regiones[Skill],'BUPA Seguros'!$L$3) -> 0 | F15: 0 | G15: =IFERROR(SUMIFS(Regiones[TMO],Regiones[Fecha],Tabla54[[#This Row],[Fecha]],Regiones[Intervalo],Tabla54[[#This Row],[Intervalo]],Regiones[Skill],'BUPA Seguros'!$L$3)/Tabla54[[#This Row],[Atendidas]],0) -> 0 | H15: =IFERROR(SUMIFS(Regiones[Aten < 20 seg],Regiones[Fecha],Tabla54[[#This Row],[Fecha]],Regiones[Intervalo],Tabla54[[#This Row],[Intervalo]],Regiones[Skill],'BUPA Seguros'!$L$3)/Tabla54[[#This Row],[Recibidas]],0) -> 0 | I15: =IFERROR(Tabla54[[#This Row],[Atendidas]]/Tabla54[[#This Row],[Recibidas]],0) -> 0 | L15: =+L14+1 -> 46214 | M15: =+SUMIFS(Tabla54[Forecast],Tabla54[Fecha],$L15) -> 0 | N15: =+SUMIFS(Regiones[Ofrecidas],Regiones[Fecha2],'BUPA Seguros'!$L15,Regiones[Skill],'BUPA Seguros'!$L$3) -> 0 | P15: =+SUMIFS(Regiones[Contestadas],Regiones[Fecha2],'BUPA Seguros'!$L15,Regiones[Skill],'BUPA Seguros'!$L$3) -> 0 | Q15: =+SUMIFS(Regiones[Aten < 20 seg],Regiones[Fecha2],'BUPA Seguros'!$L15,Regiones[Skill],'BUPA Seguros'!$L$3) -> 0 | R15: =+N15-P15 -> 0 | S15: =IFERROR(R15/N15,"") | T15: =IFERROR(Q15/N15,"") | U15: =IFERROR(P15/N15,"") | W15: 0.47916667 | X15: =+SUMIFS(Tabla54[Recibidas],Tabla54[Fecha],$X$3,Tabla54[Intervalo],$W15) -> 0 | Y15: =+SUMIFS(Tabla54[Forecast],Tabla54[Fecha],$X$3,Tabla54[Intervalo],$W15) -> 55.135698 | Z15: =+SUMIFS(Tabla54[Atendidas],Tabla54[Fecha],$X$3,Tabla54[Intervalo],$W15) -> 0 | AA15: =+X15-Z15 -> 0 | AB15: =+SUMIFS(Regiones[Aten < 20 seg],Regiones[Fecha],'BUPA Seguros'!$X$3,Regiones[Intervalo],'BUPA Seguros'!$W15,Regiones[Skill],'BUPA Seguros'!$L$3) -> 0
B16: =+B15 -> 46204 | C16: 0.20833333 | D16: =+SUMIFS(Regiones[Ofrecidas],Regiones[Fecha],Tabla54[[#This Row],[Fecha]],Regiones[Intervalo],Tabla54[[#This Row],[Intervalo]],Regiones[Skill],'BUPA Seguros'!$L$3) -> 0 | E16: =+SUMIFS(Regiones[Contestadas],Regiones[Fecha],Tabla54[[#This Row],[Fecha]],Regiones[Intervalo],Tabla54[[#This Row],[Intervalo]],Regiones[Skill],'BUPA Seguros'!$L$3) -> 0 | F16: 0 | G16: =IFERROR(SUMIFS(Regiones[TMO],Regiones[Fecha],Tabla54[[#This Row],[Fecha]],Regiones[Intervalo],Tabla54[[#This Row],[Intervalo]],Regiones[Skill],'BUPA Seguros'!$L$3)/Tabla54[[#This Row],[Atendidas]],0) -> 0 | H16: =IFERROR(SUMIFS(Regiones[Aten < 20 seg],Regiones[Fecha],Tabla54[[#This Row],[Fecha]],Regiones[Intervalo],Tabla54[[#This Row],[Intervalo]],Regiones[Skill],'BUPA Seguros'!$L$3)/Tabla54[[#This Row],[Recibidas]],0) -> 0 | I16: =IFERROR(Tabla54[[#This Row],[Atendidas]]/Tabla54[[#This Row],[Recibidas]],0) -> 0 | L16: =+L15+1 -> 46215 | M16: =+SUMIFS(Tabla54[Forecast],Tabla54[Fecha],$L16) -> 0 | N16: =+SUMIFS(Regiones[Ofrecidas],Regiones[Fecha2],'BUPA Seguros'!$L16,Regiones[Skill],'BUPA Seguros'!$L$3) -> 0 | P16: =+SUMIFS(Regiones[Contestadas],Regiones[Fecha2],'BUPA Seguros'!$L16,Regiones[Skill],'BUPA Seguros'!$L$3) -> 0 | Q16: =+SUMIFS(Regiones[Aten < 20 seg],Regiones[Fecha2],'BUPA Seguros'!$L16,Regiones[Skill],'BUPA Seguros'!$L$3) -> 0 | R16: =+N16-P16 -> 0 | S16: =IFERROR(R16/N16,"") | T16: =IFERROR(Q16/N16,"") | U16: =IFERROR(P16/N16,"") | W16: 0.5 | X16: =+SUMIFS(Tabla54[Recibidas],Tabla54[Fecha],$X$3,Tabla54[Intervalo],$W16) -> 0 | Y16: =+SUMIFS(Tabla54[Forecast],Tabla54[Fecha],$X$3,Tabla54[Intervalo],$W16) -> 54.085494 | Z16: =+SUMIFS(Tabla54[Atendidas],Tabla54[Fecha],$X$3,Tabla54[Intervalo],$W16) -> 0 | AA16: =+X16-Z16 -> 0 | AB16: =+SUMIFS(Regiones[Aten < 20 seg],Regiones[Fecha],'BUPA Seguros'!$X$3,Regiones[Intervalo],'BUPA Seguros'!$W16,Regiones[Skill],'BUPA Seguros'!$L$3) -> 0
B17: =+B16 -> 46204 | C17: 0.22916667 | D17: =+SUMIFS(Regiones[Ofrecidas],Regiones[Fecha],Tabla54[[#This Row],[Fecha]],Regiones[Intervalo],Tabla54[[#This Row],[Intervalo]],Regiones[Skill],'BUPA Seguros'!$L$3) -> 0 | E17: =+SUMIFS(Regiones[Contestadas],Regiones[Fecha],Tabla54[[#This Row],[Fecha]],Regiones[Intervalo],Tabla54[[#This Row],[Intervalo]],Regiones[Skill],'BUPA Seguros'!$L$3) -> 0 | F17: 0 | G17: =IFERROR(SUMIFS(Regiones[TMO],Regiones[Fecha],Tabla54[[#This Row],[Fecha]],Regiones[Intervalo],Tabla54[[#This Row],[Intervalo]],Regiones[Skill],'BUPA Seguros'!$L$3)/Tabla54[[#This Row],[Atendidas]],0) -> 0 | H17: =IFERROR(SUMIFS(Regiones[Aten < 20 seg],Regiones[Fecha],Tabla54[[#This Row],[Fecha]],Regiones[Intervalo],Tabla54[[#This Row],[Intervalo]],Regiones[Skill],'BUPA Seguros'!$L$3)/Tabla54[[#This Row],[Recibidas]],0) -> 0 | I17: =IFERROR(Tabla54[[#This Row],[Atendidas]]/Tabla54[[#This Row],[Recibidas]],0) -> 0 | L17: =+L16+1 -> 46216 | M17: =+SUMIFS(Tabla54[Forecast],Tabla54[Fecha],$L17) -> 821.61119 | N17: =+SUMIFS(Regiones[Ofrecidas],Regiones[Fecha2],'BUPA Seguros'!$L17,Regiones[Skill],'BUPA Seguros'!$L$3) -> 0 | P17: =+SUMIFS(Regiones[Contestadas],Regiones[Fecha2],'BUPA Seguros'!$L17,Regiones[Skill],'BUPA Seguros'!$L$3) -> 0 | Q17: =+SUMIFS(Regiones[Aten < 20 seg],Regiones[Fecha2],'BUPA Seguros'!$L17,Regiones[Skill],'BUPA Seguros'!$L$3) -> 0 | R17: =+N17-P17 -> 0 | S17: =IFERROR(R17/N17,"") | T17: =IFERROR(Q17/N17,"") | U17: =IFERROR(P17/N17,"") | W17: 0.52083333 | X17: =+SUMIFS(Tabla54[Recibidas],Tabla54[Fecha],$X$3,Tabla54[Intervalo],$W17) -> 0 | Y17: =+SUMIFS(Tabla54[Forecast],Tabla54[Fecha],$X$3,Tabla54[Intervalo],$W17) -> 50.14723 | Z17: =+SUMIFS(Tabla54[Atendidas],Tabla54[Fecha],$X$3,Tabla54[Intervalo],$W17) -> 0 | AA17: =+X17-Z17 -> 0 | AB17: =+SUMIFS(Regiones[Aten < 20 seg],Regiones[Fecha],'BUPA Seguros'!$X$3,Regiones[Intervalo],'BUPA Seguros'!$W17,Regiones[Skill],'BUPA Seguros'!$L$3) -> 0
B18: =+B17 -> 46204 | C18: 0.25 | D18: =+SUMIFS(Regiones[Ofrecidas],Regiones[Fecha],Tabla54[[#This Row],[Fecha]],Regiones[Intervalo],Tabla54[[#This Row],[Intervalo]],Regiones[Skill],'BUPA Seguros'!$L$3) -> 0 | E18: =+SUMIFS(Regiones[Contestadas],Regiones[Fecha],Tabla54[[#This Row],[Fecha]],Regiones[Intervalo],Tabla54[[#This Row],[Intervalo]],Regiones[Skill],'BUPA Seguros'!$L$3) -> 0 | F18: 0 | G18: =IFERROR(SUMIFS(Regiones[TMO],Regiones[Fecha],Tabla54[[#This Row],[Fecha]],Regiones[Intervalo],Tabla54[[#This Row],[Intervalo]],Regiones[Skill],'BUPA Seguros'!$L$3)/Tabla54[[#This Row],[Atendidas]],0) -> 0 | H18: =IFERROR(SUMIFS(Regiones[Aten < 20 seg],Regiones[Fecha],Tabla54[[#This Row],[Fecha]],Regiones[Intervalo],Tabla54[[#This Row],[Intervalo]],Regiones[Skill],'BUPA Seguros'!$L$3)/Tabla54[[#This Row],[Recibidas]],0) -> 0 | I18: =IFERROR(Tabla54[[#This Row],[Atendidas]]/Tabla54[[#This Row],[Recibidas]],0) -> 0 | L18: =+L17+1 -> 46217 | M18: =+SUMIFS(Tabla54[Forecast],Tabla54[Fecha],$L18) -> 684.10661 | N18: =+SUMIFS(Regiones[Ofrecidas],Regiones[Fecha2],'BUPA Seguros'!$L18,Regiones[Skill],'BUPA Seguros'!$L$3) -> 0 | P18: =+SUMIFS(Regiones[Contestadas],Regiones[Fecha2],'BUPA Seguros'!$L18,Regiones[Skill],'BUPA Seguros'!$L$3) -> 0 | Q18: =+SUMIFS(Regiones[Aten < 20 seg],Regiones[Fecha2],'BUPA Seguros'!$L18,Regiones[Skill],'BUPA Seguros'!$L$3) -> 0 | R18: =+N18-P18 -> 0 | S18: =IFERROR(R18/N18,"") | T18: =IFERROR(Q18/N18,"") | U18: =IFERROR(P18/N18,"") | W18: 0.54166667 | X18: =+SUMIFS(Tabla54[Recibidas],Tabla54[Fecha],$X$3,Tabla54[Intervalo],$W18) -> 0 | Y18: =+SUMIFS(Tabla54[Forecast],Tabla54[Fecha],$X$3,Tabla54[Intervalo],$W18) -> 47.31168 | Z18: =+SUMIFS(Tabla54[Atendidas],Tabla54[Fecha],$X$3,Tabla54[Intervalo],$W18) -> 0 | AA18: =+X18-Z18 -> 0 | AB18: =+SUMIFS(Regiones[Aten < 20 seg],Regiones[Fecha],'BUPA Seguros'!$X$3,Regiones[Intervalo],'BUPA Seguros'!$W18,Regiones[Skill],'BUPA Seguros'!$L$3) -> 0
